Workbook

Sheet WBS
A1: › WORK BREAKDOWN STRUCTURE — REVOPS ASSESSMENT B2B E B2C · LAICA S.P.A.
A2: # | B2: Cod. WBS | C2: Fase | D2: Tipo | E2: Modalità | F2: Blocco | G2: Sett. inizio | H2: Durata (sett.) | I2: Sett. fine | J2: Descrizione | K2: Attività preparatorie | L2: Attività di follow-up | M2: Input dal cliente | N2: Output / Deliverable | O2: Owner | P2: Partecipanti | Q2: N. incontri | R2: Durata incontro (h) | S2: N. persone | T2: gg Front office | U2: gg Back office | V2: gg Viaggio | W2: Delivery (composizione team) | X2: Tot. giornate | Y2: Ore totali | Z2: Costo totale | AA2: Note
A3: 1 | B3: 1.1 | C3: Kick-off e analisi preliminare dei dati | D3: Cliente | E3: Remoto | F3: 1 · Avvio | G3: 1 | H3: 2 | I3: =IF(AND(G3<>"",H3<>""),G3+H3-1,"") | J3: Incontro di avvio in remoto che sancisce l'apertura ufficiale del progetto: allineamento sulla governance, presentazione dei team e delle regole d'ingaggio tra tutti gli attori operativi e decisionali, condivisione della roadmap progettuale e del piano temporale di dettaglio con le date delle sessioni. Nella stessa sede si concordano le estrazioni da CRM ed ERP necessarie a comprendere la struttura dei dati di clienti e ordini, i punti di accesso all'informazione e la gestione dati attuale. L'analisi della base dati è condotta in modalità asincrona dai consulenti. | K3: Convocazione dell'incontro a cura del Commerciale; predisposizione delle slide di kick-off e della proposta di piano temporale (Gantt). | L3: E-mail di debrief con slide di kick-off e piano di lavoro definitivo allegati in PDF; analisi asincrona delle estrazioni ricevute. | M3: Estrazioni da CRM ed ERP su clienti e ordini; contatti dei referenti di progetto con adeguata autorità decisionale. | N3: Governance di progetto condivisa · piano temporale definitivo · e-mail di debrief con slide e piano in PDF · analisi preliminare della base dati. | O3: Commerciale (convocazione) → Project Manager (presidio) | P3: Impresoft: 3 persone. Laica: Managing Director, CMO, CFO, CSO, referenti gestione dati / IT. | Q3: 1 | R3: 1.5 | S3: 3 | T3: =IF(OR(Q3="",R3="",S3=""),0,Q3*R3*S3/Parametri!$C$6) | U3: 3 | V3: =IF(AND(E3="In presenza",Q3<>"",S3<>""),Q3*S3*Parametri!$C$10/Parametri!$C$6,0) | W3: 3 persone in remoto (1 RevOps Consultant Senior + 2 junior) | X3: =T3+U3+V3 | Y3: =X3*Parametri!$C$6 | Z3: =T3*Parametri!$C$6*Parametri!$C$7+U3*Parametri!$C$6*Parametri!$C$8+V3*Parametri!$C$6*Parametri!$C$9 | AA3: Offerta § 6.1 — 90 minuti, remoto. Il contratto indica 2 risorse Impresoft (PM + RevOps Consultant): qui sono 3 per scelta di pianificazione. L'analisi dati non è un momento erogato al cliente: è back office dentro questa fase. gg back office: STIMA, non desunta dal contratto.
A4: 2 | B4: 1.2 | C4: Workshop #1 — Revenue model B2B e B2C | D4: Cliente | E4: In presenza | F4: 2 · Workshop | G4: 3 | H4: 1 | I4: =IF(AND(G4<>"",H4<>""),G4+H4-1,"") | J4: Workshop in presenza per mappare le modalità con cui Laica genera valore sul canale B2B (distribuzione e OEM) e sui canali digitali B2C. Si analizza la proposta di valore per segmento, si mappano i canali di vendita e si esamina la struttura dei ricavi tra vendita dell'hardware e prodotti consumabili, costruendo il Revenue Model completo: value proposition, segmenti di clientela, competitor, canali, attività e risorse chiave, fonti di ricavo core, up-selling e cross-selling. | K4: Predisposizione del framework Revenue Model e condivisione dell'agenda. | L4: Compilazione del file di delivery, formalizzazione della mappa e restituzione al cliente; registrazione delle evidenze emerse. | M4: Disponibilità dei referenti di canale; dati di ricavo per linea di prodotto e per canale. | N4: Mappa formale del Revenue Model articolata per il canale B2B OEM e per i canali B2C. | O4: Project Manager | P4: Impresoft: 3 persone. Laica: Managing Director, Marketing Manager, CFO, CSO. | Q4: 1 | R4: 6 | S4: 3 | T4: =IF(OR(Q4="",R4="",S4=""),0,Q4*R4*S4/Parametri!$C$6) | U4: 1.5 | V4: =IF(AND(E4="In presenza",Q4<>"",S4<>""),Q4*S4*Parametri!$C$10/Parametri!$C$6,0) | W4: 3 persone in presenza (1 RevOps Consultant Senior + 2 junior) | X4: =T4+U4+V4 | Y4: =X4*Parametri!$C$6 | Z4: =T4*Parametri!$C$6*Parametri!$C$7+U4*Parametri!$C$6*Parametri!$C$8+V4*Parametri!$C$6*Parametri!$C$9 | AA4: Offerta § 6.2 — 6 ore, in presenza, UN SOLO incontro per entrambi i canali. gg back office: STIMA.
A5: 3 | B5: 1.3 | C5: Workshop #2 — ICP, target group e customer journey | D5: Cliente | E5: In presenza | F5: 2 · Workshop | G5: 4 | H5: 1 | I5: =IF(AND(G5<>"",H5<>""),G5+H5-1,"") | J5: Due sessioni in presenza — una dedicata al B2B/OEM e una al B2C/D2C — per definire i profili di cliente target e ricostruire il percorso d'acquisto nei mercati di riferimento. L'Ideal Customer Profile è costruito con metodologia SPICED; il customer journey è mappato lungo le fasi di acquisizione ed espansione del bowtie (consapevolezza, educazione, vendita, onboarding, soddisfazione, espansione), con la mappatura B2C estesa ai touchpoint proprietari e ai marketplace. | K5: Predisposizione delle schede ICP e della struttura di journey; condivisione dell'agenda delle due sessioni. | L5: Compilazione del file di delivery, formalizzazione delle schede e della mappa, restituzione al cliente; registrazione delle evidenze emerse. | M5: Disponibilità dei referenti marketing e sales per entrambe le sessioni. | N5: Schede ICP B2B e B2C per segmento · mappa dettagliata del Customer Journey multicanale. | O5: Project Manager | P5: Impresoft: 3 persone. Laica: Managing Director, Marketing Manager, CFO, CSO. | Q5: 2 | R5: 6 | S5: 3 | T5: =IF(OR(Q5="",R5="",S5=""),0,Q5*R5*S5/Parametri!$C$6) | U5: 2 | V5: =IF(AND(E5="In presenza",Q5<>"",S5<>""),Q5*S5*Parametri!$C$10/Parametri!$C$6,0) | W5: 3 persone in presenza × 2 sessioni (1 RevOps Consultant Senior + 2 junior) | X5: =T5+U5+V5 | Y5: =X5*Parametri!$C$6 | Z5: =T5*Parametri!$C$6*Parametri!$C$7+U5*Parametri!$C$6*Parametri!$C$8+V5*Parametri!$C$6*Parametri!$C$9 | AA5: Offerta § 6.3 — 12 ore complessive: 2 workshop dedicati (B2B + B2C) di circa 6 ore ciascuno, in presenza. È la fase più pesante del progetto. gg back office: STIMA.
A6: 4 | B6: 1.4 | C6: Workshop #3 — Process design | D6: Cliente | E6: In presenza | F6: 2 · Workshop | G6: 5 | H6: 1 | I6: =IF(AND(G6<>"",H6<>""),G6+H6-1,"") | J6: Workshop in presenza per mappare i flussi operativi correnti tra i dipartimenti: processi di Marketing, Sales, Service e Operations, con i relativi flussi e frizioni as-is. Si rileva cosa funziona e cosa non funziona nei processi in essere e si identificano i gap rispetto allo stato desiderato definito nel customer journey. | K6: Raccolta della documentazione di processo esistente; condivisione dell'agenda. | L6: Compilazione del file di delivery; avvio del diagramma dei flussi di processo as-is. | M6: Documentazione di processo; disponibilità dei process owner. | N6: Diagramma dei flussi di processo as-is — contributo del workshop alla gap analysis. | O6: Project Manager | P6: Impresoft: 3 persone. Laica: Marketing Manager, CSO, referente servizio clienti, key user operativi. | Q6: 1 | R6: 6 | S6: 3 | T6: =IF(OR(Q6="",R6="",S6=""),0,Q6*R6*S6/Parametri!$C$6) | U6: 2 | V6: =IF(AND(E6="In presenza",Q6<>"",S6<>""),Q6*S6*Parametri!$C$10/Parametri!$C$6,0) | W6: 3 persone in presenza (1 RevOps Consultant Senior + 2 junior) | X6: =T6+U6+V6 | Y6: =X6*Parametri!$C$6 | Z6: =T6*Parametri!$C$6*Parametri!$C$7+U6*Parametri!$C$6*Parametri!$C$8+V6*Parametri!$C$6*Parametri!$C$9 | AA6: Offerta § 6.4 — 6 ore, in presenza. Il perimetro contrattuale copre Marketing, Sales, Service e Operations. Nel contratto process design e user research sono un unico workshop: le interviste sono tenute su una riga a parte per separare i blocchi di progetto. gg back office: STIMA.
A7: 5 | B7: 1.5 | C7: Interviste one-to-one — user research | D7: Cliente | E7: Remoto | F7: 3 · User research | G7: 6 | H7: 1 | I7: =IF(AND(G7<>"",H7<>""),G7+H7-1,"") | J7: Cinque interviste individuali alle persone chiave di sales, marketing e customer care, condotte a valle del process design da un solo consulente. Sono interviste qualitative volte a raccogliere insight su come i processi sono vissuti quotidianamente e a far emergere le frizioni operative e tecnologiche che la mappatura di processo non rende visibili. | K7: Selezione degli intervistati con il cliente; predisposizione della guida di intervista. | L7: Sintesi trasversale delle interviste e integrazione nel documento di gap analysis. | M7: Individuazione e disponibilità delle 5 persone chiave da intervistare. | N7: Insight qualitativi · documento di sintesi dei punti di attrito operativi (gap analysis). | O7: Project Manager | P7: Impresoft: 1 RevOps Consultant junior. Laica: 5 persone chiave di sales, marketing e customer care. | Q7: 5 | R7: 1 | S7: 1 | T7: =IF(OR(Q7="",R7="",S7=""),0,Q7*R7*S7/Parametri!$C$6) | U7: 1 | V7: =IF(AND(E7="In presenza",Q7<>"",S7<>""),Q7*S7*Parametri!$C$10/Parametri!$C$6,0) | W7: 1 persona in remoto (1 RevOps Consultant junior) | X7: =T7+U7+V7 | Y7: =X7*Parametri!$C$6 | Z7: =T7*Parametri!$C$6*Parametri!$C$7+U7*Parametri!$C$6*Parametri!$C$8+V7*Parametri!$C$6*Parametri!$C$9 | AA7: Offerta § 6.4 — il contratto fissa 5 interviste one-to-one ma NON la loro durata: 1 ora ciascuna è una stima. Attività compresa nel Workshop #3, isolata qui come blocco a sé. gg back office: STIMA.
A8: 6 | B8: 1.6 | C8: Workshop #4 — Tech stack e data governance | D8: Cliente | E8: Remoto | F8: 2 · Workshop | G8: 6 | H8: 1 | I8: =IF(AND(G8<>"",H8<>""),G8+H8-1,"") | J8: Sessione in remoto per mappare le applicazioni in uso che impattano i processi di go-to-market: CRM HubSpot, gestionale/ERP, e-commerce, connettori marketplace. Si individua dove risiede l'informazione, come i dati fluiscono tra i sistemi e si analizzano le integrazioni esistenti, con l'obiettivo di fotografare lo stack as-is. | K8: Richiesta preventiva dell'inventario applicativo e delle licenze in essere. | L8: Compilazione del file di delivery; formalizzazione della mappa architetturale e degli schemi di integrazione. | M8: Inventario degli strumenti in uso; accesso ai referenti IT e, se necessario, ai fornitori software esterni. | N8: Mappa dell'architettura applicativa corrente · schema dei flussi di integrazione dati. | O8: Project Manager | P8: Impresoft: 3 persone. Laica: referenti IT / sistemi informativi, key user di processo, eventuali fornitori software esterni. | Q8: 1 | R8: 4 | S8: 3 | T8: =IF(OR(Q8="",R8="",S8=""),0,Q8*R8*S8/Parametri!$C$6) | U8: 1.5 | V8: =IF(AND(E8="In presenza",Q8<>"",S8<>""),Q8*S8*Parametri!$C$10/Parametri!$C$6,0) | W8: 3 persone in remoto (1 RevOps Consultant Senior + 2 junior) | X8: =T8+U8+V8 | Y8: =X8*Parametri!$C$6 | Z8: =T8*Parametri!$C$6*Parametri!$C$7+U8*Parametri!$C$6*Parametri!$C$8+V8*Parametri!$C$6*Parametri!$C$9 | AA8: Offerta § 6.5 — 4 ore, in remoto. gg back office: STIMA.
A9: 7 | B9: 1.7 | C9: Workshop #5 — Data model e prioritizzazione | D9: Cliente | E9: In presenza | F9: 2 · Workshop | G9: 7 | H9: 1 | I9: =IF(AND(G9<>"",H9<>""),G9+H9-1,"") | J9: Workshop in presenza per definire la struttura dei dati target — modello dati unificato per la gestione di cliente e prodotto — individuando i dati da tracciare lungo il customer journey, i KPI e i criteri di transizione. Nella seconda parte si consolidano le attività emerse e si prioritizzano per impatto, velocità a impatto e semplicità, classificandole con matrice di priorità. | K9: Predisposizione dell'albero dei KPI sul bowtie e della matrice di prioritizzazione. | L9: Formalizzazione del Data Model target; consolidamento delle priorità in vista della roadmap. | M9: Disponibilità dei dati necessari ad alimentare i KPI proposti. | N9: Data Model target · classificazione degli interventi per matrice di priorità. | O9: Project Manager | P9: Impresoft: 3 persone. Laica: Managing Director, Marketing Manager, CFO, CSO, referente IT. | Q9: 1 | R9: 6 | S9: 3 | T9: =IF(OR(Q9="",R9="",S9=""),0,Q9*R9*S9/Parametri!$C$6) | U9: 1.6 | V9: =IF(AND(E9="In presenza",Q9<>"",S9<>""),Q9*S9*Parametri!$C$10/Parametri!$C$6,0) | W9: 3 persone in presenza (1 RevOps Consultant Senior + 2 junior) | X9: =T9+U9+V9 | Y9: =X9*Parametri!$C$6 | Z9: =T9*Parametri!$C$6*Parametri!$C$7+U9*Parametri!$C$6*Parametri!$C$8+V9*Parametri!$C$6*Parametri!$C$9 | AA9: Offerta § 6.6 — 6 ore, in presenza. Il contratto indica 4 risorse Impresoft sul § 6.6 (RevOps Consultant, CX Specialist, Integration Expert, PM): qui sono 3. La roadmap per wave non è una fase: è contenuto del report finale. gg back office: STIMA.
A10: 8 | B10: 1.8 | C10: Review con il cliente | D10: Cliente | E10: Remoto | F10: 4 · Sintesi e validazione | G10: 9 | H10: 1 | I10: =IF(AND(G10<>"",H10<>""),G10+H10-1,"") | J10: Incontro di validazione con il team di lavoro lato cliente sui business case e sulle priorità consolidate, prima della formalizzazione del report. Si verifica l'allineamento su priorità e numeri e si stabilisce se procedere o iterare su specifici ambiti. | K10: Invio anticipato dei business case e della matrice di priorità per lettura preventiva. | L10: Recepimento delle iterazioni richieste e aggiornamento del report in costruzione. | M10: Presenza dei decisori lato cliente. | N10: Business case e priorità validati, oppure lista delle iterazioni richieste. | O10: Project Manager | P10: Impresoft: 3 persone. Laica: team di lavoro e decisori. | Q10: 1 | R10: 2 | S10: 3 | T10: =IF(OR(Q10="",R10="",S10=""),0,Q10*R10*S10/Parametri!$C$6) | U10: 0.5 | V10: =IF(AND(E10="In presenza",Q10<>"",S10<>""),Q10*S10*Parametri!$C$10/Parametri!$C$6,0) | W10: 3 persone in remoto (1 RevOps Consultant Senior + 2 junior) | X10: =T10+U10+V10 | Y10: =X10*Parametri!$C$6 | Z10: =T10*Parametri!$C$6*Parametri!$C$7+U10*Parametri!$C$6*Parametri!$C$8+V10*Parametri!$C$6*Parametri!$C$9 | AA10: FUORI PERIMETRO CONTRATTUALE — l'Offerta non prevede una sessione di review tra il Workshop #5 e il meeting di presentazione. Mantenuta su richiesta, 2 ore in remoto. gg back office: STIMA.
A11: 9 | B11: 1.9 | C11: Consolidamento report, roadmap e business case | D11: Interna | E11: Interna | F11: 4 · Sintesi e validazione | G11: 6 | H11: 5 | I11: =IF(AND(G11<>"",H11<>""),G11+H11-1,"") | J11: Fase interna di consolidamento dell'intero assessment: costruzione del report consolidato, della roadmap strategica di implementazione suddivisa per wave secondo le priorità individuate e del business case economico analitico a supporto. Il documento viene anticipato al cliente via e-mail in PDF prima del meeting di presentazione. | K11: Consolidamento dei file di delivery di tutte le sessioni precedenti e degli esiti della review. | L11: Invio anticipato del PDF al cliente in vista del meeting di presentazione. | N11: Report consolidato di assessment · roadmap per wave · business case economico · PDF in lingua italiana. | O11: Project Manager | P11: Team di progetto | T11: =IF(OR(Q11="",R11="",S11=""),0,Q11*R11*S11/Parametri!$C$6) | U11: 4 | V11: =IF(AND(E11="In presenza",Q11<>"",S11<>""),Q11*S11*Parametri!$C$10/Parametri!$C$6,0) | X11: =T11+U11+V11 | Y11: =X11*Parametri!$C$6 | Z11: =T11*Parametri!$C$6*Parametri!$C$7+U11*Parametri!$C$6*Parametri!$C$8+V11*Parametri!$C$6*Parametri!$C$9 | AA11: Offerta § 6.6 e § 11 — l'invio anticipato del PDF è la milestone che attiva la fatturazione del 50% residuo. gg back office: STIMA, ed è la voce più pesante del progetto.
A12: 10 | B12: 1.10 | C12: Meeting di presentazione dell'output | D12: Cliente | E12: In presenza | F12: 5 · Chiusura | G12: 10 | H12: 1 | I12: =IF(AND(G12<>"",H12<>""),G12+H12-1,"") | J12: Presentazione in presenza dell'output finale dell'assessment — report consolidato, roadmap per wave e business case — come passaggio verso le successive scelte di investimento tecnologico e organizzativo. Si svolge circa 15 giorni dopo il workshop Data Model. | K12: Predisposizione delle slide di presentazione; conferma di agenda e partecipanti. | L12: Raccolta delle precisazioni e micro-rettifiche emerse in incontro, da recepire nella versione inglese del report. | M12: Presenza dei decisori lato cliente. | N12: Assessment presentato e consegnato · next step condivisi. | O12: Project Manager | P12: Impresoft: 3 persone. Laica: Managing Director, Marketing Manager, CFO, CSO, referente IT. | Q12: 1 | R12: 2 | S12: 3 | T12: =IF(OR(Q12="",R12="",S12=""),0,Q12*R12*S12/Parametri!$C$6) | U12: 1 | V12: =IF(AND(E12="In presenza",Q12<>"",S12<>""),Q12*S12*Parametri!$C$10/Parametri!$C$6,0) | W12: 3 persone in presenza (1 RevOps Consultant Senior + 2 junior) | X12: =T12+U12+V12 | Y12: =X12*Parametri!$C$6 | Z12: =T12*Parametri!$C$6*Parametri!$C$7+U12*Parametri!$C$6*Parametri!$C$8+V12*Parametri!$C$6*Parametri!$C$9 | AA12: Offerta § 6.6 — 2 ore, in presenza, circa 15 giorni dopo il Workshop #5. VINCOLO DI PIANIFICAZIONE da rispettare nella colonna «Sett. inizio». gg back office: STIMA.
A13: 11 | B13: 1.11 | C13: Redazione output in lingua inglese | D13: Interna | E13: Interna | F13: 5 · Chiusura | G13: 10 | H13: 1 | I13: =IF(AND(G13<>"",H13<>""),G13+H13-1,"") | J13: Redazione della versione inglese del report di assessment, che il contratto colloca esplicitamente dopo il meeting di presentazione per poter includere le precisazioni e le micro-rettifiche emerse durante l'incontro. | K13: Recepimento delle rettifiche emerse in presentazione. | L13: Consegna del PDF in lingua inglese. | N13: Report di assessment in lingua inglese (PDF). | O13: Project Manager | P13: Team di progetto | T13: =IF(OR(Q13="",R13="",S13=""),0,Q13*R13*S13/Parametri!$C$6) | U13: 0.5 | V13: =IF(AND(E13="In presenza",Q13<>"",S13<>""),Q13*S13*Parametri!$C$10/Parametri!$C$6,0) | X13: =T13+U13+V13 | Y13: =X13*Parametri!$C$6 | Z13: =T13*Parametri!$C$6*Parametri!$C$7+U13*Parametri!$C$6*Parametri!$C$8+V13*Parametri!$C$6*Parametri!$C$9 | AA13: Offerta § 6.6 — deliverable obbligatorio. ATTENZIONE: il § 6.7 esclude dall'offerta la «traduzione di testi» come servizio di terze parti, quindi la versione inglese è a carico interno. Questa coda cade OLTRE le 10 settimane dichiarate al § 8. gg back office: STIMA.
A14: TOTALE PROGETTO | Q14: =SUM(Q3:Q13) | T14: =SUM(T3:T13) | U14: =SUM(U3:U13) | V14: =SUM(V3:V13) | X14: =SUM(X3:X13) | Y14: =SUM(Y3:Y13) | Z14: =SUM(Z3:Z13)

Sheet Timeline
A1: › TIMELINE DI PROGETTO — SETTIMANE RELATIVE SU CALENDARIO REALE
A2: Parti dalla settimana ISO › | F2: 41 | G2: =CHOOSE(MONTH(DATE(Parametri!$C$15,1,4)-WEEKDAY(DATE(Parametri!$C$15,1,4),3)+7*(G$3-1)),"Gen","Feb","Mar","Apr","Mag","Giu","Lug","Ago","Set","Ott","Nov","Dic") | H2: =CHOOSE(MONTH(DATE(Parametri!$C$15,1,4)-WEEKDAY(DATE(Parametri!$C$15,1,4),3)+7*(H$3-1)),"Gen","Feb","Mar","Apr","Mag","Giu","Lug","Ago","Set","Ott","Nov","Dic") | I2: =CHOOSE(MONTH(DATE(Parametri!$C$15,1,4)-WEEKDAY(DATE(Parametri!$C$15,1,4),3)+7*(I$3-1)),"Gen","Feb","Mar","Apr","Mag","Giu","Lug","Ago","Set","Ott","Nov","Dic") | J2: =CHOOSE(MONTH(DATE(Parametri!$C$15,1,4)-WEEKDAY(DATE(Parametri!$C$15,1,4),3)+7*(J$3-1)),"Gen","Feb","Mar","Apr","Mag","Giu","Lug","Ago","Set","Ott","Nov","Dic") | K2: =CHOOSE(MONTH(DATE(Parametri!$C$15,1,4)-WEEKDAY(DATE(Parametri!$C$15,1,4),3)+7*(K$3-1)),"Gen","Feb","Mar","Apr","Mag","Giu","Lug","Ago","Set","Ott","Nov","Dic") | L2: =CHOOSE(MONTH(DATE(Parametri!$C$15,1,4)-WEEKDAY(DATE(Parametri!$C$15,1,4),3)+7*(L$3-1)),"Gen","Feb","Mar","Apr","Mag","Giu","Lug","Ago","Set","Ott","Nov","Dic") | M2: =CHOOSE(MONTH(DATE(Parametri!$C$15,1,4)-WEEKDAY(DATE(Parametri!$C$15,1,4),3)+7*(M$3-1)),"Gen","Feb","Mar","Apr","Mag","Giu","Lug","Ago","Set","Ott","Nov","Dic") | N2: =CHOOSE(MONTH(DATE(Parametri!$C$15,1,4)-WEEKDAY(DATE(Parametri!$C$15,1,4),3)+7*(N$3-1)),"Gen","Feb","Mar","Apr","Mag","Giu","Lug","Ago","Set","Ott","Nov","Dic") | ... R2: =CHOOSE(MONTH(DATE(Parametri!$C$15,1,4)-WEEKDAY(DATE(Parametri!$C$15,1,4),3)+7*(R$3-1)),"Gen","Feb","Mar","Apr","Mag","Giu","Lug","Ago","Set","Ott","Nov","Dic")
A3: # | B3: Fase | C3: Tipo | D3: Blocco | E3: Da sett. | F3: A sett. | G3: =$F$2+0 | H3: =$F$2+1 | I3: =$F$2+2 | J3: =$F$2+3 | K3: =$F$2+4 | L3: =$F$2+5 | M3: =$F$2+6 | N3: =$F$2+7 | O3: =$F$2+8 | P3: =$F$2+9 | Q3: =$F$2+10 | R3: =$F$2+11
A4: Settimane con fasi in parallelo › | G4: =IF(G16>1,"›","") | H4: =IF(H16>1,"›","") | I4: =IF(I16>1,"›","") | J4: =IF(J16>1,"›","") | K4: =IF(K16>1,"›","") | L4: =IF(L16>1,"›","") | M4: =IF(M16>1,"›","") | N4: =IF(N16>1,"›","") | ... R4: =IF(R16>1,"›","")
A5: =WBS!A3 | B5: =WBS!C3 | C5: =WBS!D3 | D5: =WBS!F3 | E5: =WBS!G3 | F5: =WBS!I3 | G5: =IF(AND($E5<>"",$F5<>"",$E5<=1,$F5>=1),1,"") | H5: =IF(AND($E5<>"",$F5<>"",$E5<=2,$F5>=2),1,"") | I5: =IF(AND($E5<>"",$F5<>"",$E5<=3,$F5>=3),1,"") | J5: =IF(AND($E5<>"",$F5<>"",$E5<=4,$F5>=4),1,"") | K5: =IF(AND($E5<>"",$F5<>"",$E5<=5,$F5>=5),1,"") | L5: =IF(AND($E5<>"",$F5<>"",$E5<=6,$F5>=6),1,"") | M5: =IF(AND($E5<>"",$F5<>"",$E5<=7,$F5>=7),1,"") | N5: =IF(AND($E5<>"",$F5<>"",$E5<=8,$F5>=8),1,"") | O5: =IF(AND($E5<>"",$F5<>"",$E5<=9,$F5>=9),1,"") | P5: =IF(AND($E5<>"",$F5<>"",$E5<=10,$F5>=10),1,"") | Q5: =IF(AND($E5<>"",$F5<>"",$E5<=11,$F5>=11),1,"") | R5: =IF(AND($E5<>"",$F5<>"",$E5<=12,$F5>=12),1,"")
A6: =WBS!A4 | B6: =WBS!C4 | C6: =WBS!D4 | D6: =WBS!F4 | E6: =WBS!G4 | F6: =WBS!I4 | G6: =IF(AND($E6<>"",$F6<>"",$E6<=1,$F6>=1),1,"") | H6: =IF(AND($E6<>"",$F6<>"",$E6<=2,$F6>=2),1,"") | I6: =IF(AND($E6<>"",$F6<>"",$E6<=3,$F6>=3),1,"") | J6: =IF(AND($E6<>"",$F6<>"",$E6<=4,$F6>=4),1,"") | K6: =IF(AND($E6<>"",$F6<>"",$E6<=5,$F6>=5),1,"") | L6: =IF(AND($E6<>"",$F6<>"",$E6<=6,$F6>=6),1,"") | M6: =IF(AND($E6<>"",$F6<>"",$E6<=7,$F6>=7),1,"") | N6: =IF(AND($E6<>"",$F6<>"",$E6<=8,$F6>=8),1,"") | O6: =IF(AND($E6<>"",$F6<>"",$E6<=9,$F6>=9),1,"") | P6: =IF(AND($E6<>"",$F6<>"",$E6<=10,$F6>=10),1,"") | Q6: =IF(AND($E6<>"",$F6<>"",$E6<=11,$F6>=11),1,"") | R6: =IF(AND($E6<>"",$F6<>"",$E6<=12,$F6>=12),1,"")
A7: =WBS!A5 | B7: =WBS!C5 | C7: =WBS!D5 | D7: =WBS!F5 | E7: =WBS!G5 | F7: =WBS!I5 | G7: =IF(AND($E7<>"",$F7<>"",$E7<=1,$F7>=1),1,"") | H7: =IF(AND($E7<>"",$F7<>"",$E7<=2,$F7>=2),1,"") | I7: =IF(AND($E7<>"",$F7<>"",$E7<=3,$F7>=3),1,"") | J7: =IF(AND($E7<>"",$F7<>"",$E7<=4,$F7>=4),1,"") | K7: =IF(AND($E7<>"",$F7<>"",$E7<=5,$F7>=5),1,"") | L7: =IF(AND($E7<>"",$F7<>"",$E7<=6,$F7>=6),1,"") | M7: =IF(AND($E7<>"",$F7<>"",$E7<=7,$F7>=7),1,"") | N7: =IF(AND($E7<>"",$F7<>"",$E7<=8,$F7>=8),1,"") | O7: =IF(AND($E7<>"",$F7<>"",$E7<=9,$F7>=9),1,"") | P7: =IF(AND($E7<>"",$F7<>"",$E7<=10,$F7>=10),1,"") | Q7: =IF(AND($E7<>"",$F7<>"",$E7<=11,$F7>=11),1,"") | R7: =IF(AND($E7<>"",$F7<>"",$E7<=12,$F7>=12),1,"")
A8: =WBS!A6 | B8: =WBS!C6 | C8: =WBS!D6 | D8: =WBS!F6 | E8: =WBS!G6 | F8: =WBS!I6 | G8: =IF(AND($E8<>"",$F8<>"",$E8<=1,$F8>=1),1,"") | H8: =IF(AND($E8<>"",$F8<>"",$E8<=2,$F8>=2),1,"") | I8: =IF(AND($E8<>"",$F8<>"",$E8<=3,$F8>=3),1,"") | J8: =IF(AND($E8<>"",$F8<>"",$E8<=4,$F8>=4),1,"") | K8: =IF(AND($E8<>"",$F8<>"",$E8<=5,$F8>=5),1,"") | L8: =IF(AND($E8<>"",$F8<>"",$E8<=6,$F8>=6),1,"") | M8: =IF(AND($E8<>"",$F8<>"",$E8<=7,$F8>=7),1,"") | N8: =IF(AND($E8<>"",$F8<>"",$E8<=8,$F8>=8),1,"") | O8: =IF(AND($E8<>"",$F8<>"",$E8<=9,$F8>=9),1,"") | P8: =IF(AND($E8<>"",$F8<>"",$E8<=10,$F8>=10),1,"") | Q8: =IF(AND($E8<>"",$F8<>"",$E8<=11,$F8>=11),1,"") | R8: =IF(AND($E8<>"",$F8<>"",$E8<=12,$F8>=12),1,"")
A9: =WBS!A7 | B9: =WBS!C7 | C9: =WBS!D7 | D9: =WBS!F7 | E9: =WBS!G7 | F9: =WBS!I7 | G9: =IF(AND($E9<>"",$F9<>"",$E9<=1,$F9>=1),1,"") | H9: =IF(AND($E9<>"",$F9<>"",$E9<=2,$F9>=2),1,"") | I9: =IF(AND($E9<>"",$F9<>"",$E9<=3,$F9>=3),1,"") | J9: =IF(AND($E9<>"",$F9<>"",$E9<=4,$F9>=4),1,"") | K9: =IF(AND($E9<>"",$F9<>"",$E9<=5,$F9>=5),1,"") | L9: =IF(AND($E9<>"",$F9<>"",$E9<=6,$F9>=6),1,"") | M9: =IF(AND($E9<>"",$F9<>"",$E9<=7,$F9>=7),1,"") | N9: =IF(AND($E9<>"",$F9<>"",$E9<=8,$F9>=8),1,"") | O9: =IF(AND($E9<>"",$F9<>"",$E9<=9,$F9>=9),1,"") | P9: =IF(AND($E9<>"",$F9<>"",$E9<=10,$F9>=10),1,"") | Q9: =IF(AND($E9<>"",$F9<>"",$E9<=11,$F9>=11),1,"") | R9: =IF(AND($E9<>"",$F9<>"",$E9<=12,$F9>=12),1,"")
A10: =WBS!A8 | B10: =WBS!C8 | C10: =WBS!D8 | D10: =WBS!F8 | E10: =WBS!G8 | F10: =WBS!I8 | G10: =IF(AND($E10<>"",$F10<>"",$E10<=1,$F10>=1),1,"") | H10: =IF(AND($E10<>"",$F10<>"",$E10<=2,$F10>=2),1,"") | I10: =IF(AND($E10<>"",$F10<>"",$E10<=3,$F10>=3),1,"") | J10: =IF(AND($E10<>"",$F10<>"",$E10<=4,$F10>=4),1,"") | K10: =IF(AND($E10<>"",$F10<>"",$E10<=5,$F10>=5),1,"") | L10: =IF(AND($E10<>"",$F10<>"",$E10<=6,$F10>=6),1,"") | M10: =IF(AND($E10<>"",$F10<>"",$E10<=7,$F10>=7),1,"") | N10: =IF(AND($E10<>"",$F10<>"",$E10<=8,$F10>=8),1,"") | O10: =IF(AND($E10<>"",$F10<>"",$E10<=9,$F10>=9),1,"") | P10: =IF(AND($E10<>"",$F10<>"",$E10<=10,$F10>=10),1,"") | Q10: =IF(AND($E10<>"",$F10<>"",$E10<=11,$F10>=11),1,"") | R10: =IF(AND($E10<>"",$F10<>"",$E10<=12,$F10>=12),1,"")
A11: =WBS!A9 | B11: =WBS!C9 | C11: =WBS!D9 | D11: =WBS!F9 | E11: =WBS!G9 | F11: =WBS!I9 | G11: =IF(AND($E11<>"",$F11<>"",$E11<=1,$F11>=1),1,"") | H11: =IF(AND($E11<>"",$F11<>"",$E11<=2,$F11>=2),1,"") | I11: =IF(AND($E11<>"",$F11<>"",$E11<=3,$F11>=3),1,"") | J11: =IF(AND($E11<>"",$F11<>"",$E11<=4,$F11>=4),1,"") | K11: =IF(AND($E11<>"",$F11<>"",$E11<=5,$F11>=5),1,"") | L11: =IF(AND($E11<>"",$F11<>"",$E11<=6,$F11>=6),1,"") | M11: =IF(AND($E11<>"",$F11<>"",$E11<=7,$F11>=7),1,"") | N11: =IF(AND($E11<>"",$F11<>"",$E11<=8,$F11>=8),1,"") | O11: =IF(AND($E11<>"",$F11<>"",$E11<=9,$F11>=9),1,"") | P11: =IF(AND($E11<>"",$F11<>"",$E11<=10,$F11>=10),1,"") | Q11: =IF(AND($E11<>"",$F11<>"",$E11<=11,$F11>=11),1,"") | R11: =IF(AND($E11<>"",$F11<>"",$E11<=12,$F11>=12),1,"")
A12: =WBS!A10 | B12: =WBS!C10 | C12: =WBS!D10 | D12: =WBS!F10 | E12: =WBS!G10 | F12: =WBS!I10 | G12: =IF(AND($E12<>"",$F12<>"",$E12<=1,$F12>=1),1,"") | H12: =IF(AND($E12<>"",$F12<>"",$E12<=2,$F12>=2),1,"") | I12: =IF(AND($E12<>"",$F12<>"",$E12<=3,$F12>=3),1,"") | J12: =IF(AND($E12<>"",$F12<>"",$E12<=4,$F12>=4),1,"") | K12: =IF(AND($E12<>"",$F12<>"",$E12<=5,$F12>=5),1,"") | L12: =IF(AND($E12<>"",$F12<>"",$E12<=6,$F12>=6),1,"") | M12: =IF(AND($E12<>"",$F12<>"",$E12<=7,$F12>=7),1,"") | N12: =IF(AND($E12<>"",$F12<>"",$E12<=8,$F12>=8),1,"") | O12: =IF(AND($E12<>"",$F12<>"",$E12<=9,$F12>=9),1,"") | P12: =IF(AND($E12<>"",$F12<>"",$E12<=10,$F12>=10),1,"") | Q12: =IF(AND($E12<>"",$F12<>"",$E12<=11,$F12>=11),1,"") | R12: =IF(AND($E12<>"",$F12<>"",$E12<=12,$F12>=12),1,"")
A13: =WBS!A11 | B13: =WBS!C11 | C13: =WBS!D11 | D13: =WBS!F11 | E13: =WBS!G11 | F13: =WBS!I11 | G13: =IF(AND($E13<>"",$F13<>"",$E13<=1,$F13>=1),1,"") | H13: =IF(AND($E13<>"",$F13<>"",$E13<=2,$F13>=2),1,"") | I13: =IF(AND($E13<>"",$F13<>"",$E13<=3,$F13>=3),1,"") | J13: =IF(AND($E13<>"",$F13<>"",$E13<=4,$F13>=4),1,"") | K13: =IF(AND($E13<>"",$F13<>"",$E13<=5,$F13>=5),1,"") | L13: =IF(AND($E13<>"",$F13<>"",$E13<=6,$F13>=6),1,"") | M13: =IF(AND($E13<>"",$F13<>"",$E13<=7,$F13>=7),1,"") | N13: =IF(AND($E13<>"",$F13<>"",$E13<=8,$F13>=8),1,"") | O13: =IF(AND($E13<>"",$F13<>"",$E13<=9,$F13>=9),1,"") | P13: =IF(AND($E13<>"",$F13<>"",$E13<=10,$F13>=10),1,"") | Q13: =IF(AND($E13<>"",$F13<>"",$E13<=11,$F13>=11),1,"") | R13: =IF(AND($E13<>"",$F13<>"",$E13<=12,$F13>=12),1,"")
A14: =WBS!A12 | B14: =WBS!C12 | C14: =WBS!D12 | D14: =WBS!F12 | E14: =WBS!G12 | F14: =WBS!I12 | G14: =IF(AND($E14<>"",$F14<>"",$E14<=1,$F14>=1),1,"") | H14: =IF(AND($E14<>"",$F14<>"",$E14<=2,$F14>=2),1,"") | I14: =IF(AND($E14<>"",$F14<>"",$E14<=3,$F14>=3),1,"") | J14: =IF(AND($E14<>"",$F14<>"",$E14<=4,$F14>=4),1,"") | K14: =IF(AND($E14<>"",$F14<>"",$E14<=5,$F14>=5),1,"") | L14: =IF(AND($E14<>"",$F14<>"",$E14<=6,$F14>=6),1,"") | M14: =IF(AND($E14<>"",$F14<>"",$E14<=7,$F14>=7),1,"") | N14: =IF(AND($E14<>"",$F14<>"",$E14<=8,$F14>=8),1,"") | O14: =IF(AND($E14<>"",$F14<>"",$E14<=9,$F14>=9),1,"") | P14: =IF(AND($E14<>"",$F14<>"",$E14<=10,$F14>=10),1,"") | Q14: =IF(AND($E14<>"",$F14<>"",$E14<=11,$F14>=11),1,"") | R14: =IF(AND($E14<>"",$F14<>"",$E14<=12,$F14>=12),1,"")
A15: =WBS!A13 | B15: =WBS!C13 | C15: =WBS!D13 | D15: =WBS!F13 | E15: =WBS!G13 | F15: =WBS!I13 | G15: =IF(AND($E15<>"",$F15<>"",$E15<=1,$F15>=1),1,"") | H15: =IF(AND($E15<>"",$F15<>"",$E15<=2,$F15>=2),1,"") | I15: =IF(AND($E15<>"",$F15<>"",$E15<=3,$F15>=3),1,"") | J15: =IF(AND($E15<>"",$F15<>"",$E15<=4,$F15>=4),1,"") | K15: =IF(AND($E15<>"",$F15<>"",$E15<=5,$F15>=5),1,"") | L15: =IF(AND($E15<>"",$F15<>"",$E15<=6,$F15>=6),1,"") | M15: =IF(AND($E15<>"",$F15<>"",$E15<=7,$F15>=7),1,"") | N15: =IF(AND($E15<>"",$F15<>"",$E15<=8,$F15>=8),1,"") | O15: =IF(AND($E15<>"",$F15<>"",$E15<=9,$F15>=9),1,"") | P15: =IF(AND($E15<>"",$F15<>"",$E15<=10,$F15>=10),1,"") | Q15: =IF(AND($E15<>"",$F15<>"",$E15<=11,$F15>=11),1,"") | R15: =IF(AND($E15<>"",$F15<>"",$E15<=12,$F15>=12),1,"")
A16: Fasi attive nella settimana | G16: =COUNT(G5:G15) | H16: =COUNT(H5:H15) | I16: =COUNT(I5:I15) | J16: =COUNT(J5:J15) | K16: =COUNT(K5:K15) | L16: =COUNT(L5:L15) | M16: =COUNT(M5:M15) | N16: =COUNT(N5:N15) | ... R16: =COUNT(R5:R15)
A18: Sessioni erogate al cliente (n. incontri) | F18: =WBS!Q14
A19: di cui in presenza — trasferte incluse nell'investimento | F19: =SUMPRODUCT((WBS!$E$3:$E$13="In presenza")*WBS!$Q$3:$Q$13)
A20: Settimana di massima concentrazione (n. fasi in parallelo) | F20: =MAX(G16:R16)
A21: Settimana ISO di chiusura del piano | F21: =$F$2+MAX(WBS!I3:I13)-1
A22: Periodo di calendario coperto | D22: =CHOOSE(MONTH(DATE(Parametri!$C$15,1,4)-WEEKDAY(DATE(Parametri!$C$15,1,4),3)+7*(G$3-1)),"Gennaio","Febbraio","Marzo","Aprile","Maggio","Giugno","Luglio","Agosto","Settembre","Ottobre","Novembre","Dicembre")&" "&YEAR(DATE(Parametri!$C$15,1,4)-WEEKDAY(DATE(Parametri!$C$15,1,4),3)+7*(G$3-1))&" → "&CHOOSE(MONTH(DATE(Parametri!$C$15,1,4)-WEEKDAY(DATE(Parametri!$C$15,1,4),3)+7*(R$3-1)),"Gennaio","Febbraio","Marzo","Aprile","Maggio","Giugno","Luglio","Agosto","Settembre","Ottobre","Novembre","Dicembre")&" "&YEAR(DATE(Parametri!$C$15,1,4)-WEEKDAY(DATE(Parametri!$C$15,1,4),3)+7*(R$3-1))

Sheet Riepilogo
A1: › RIEPILOGO DI PROGETTO
A2: Tutti i valori sono calcolati dalla WBS e dai Parametri. Nessuna cella di questo foglio va compilata a mano.
A4: › IMPEGNO COMPLESSIVO
A5: Giornate front office (tempo erogato al cliente) | C5: =WBS!T14 | D5: gg-uomo | E5: Calcolate da n. incontri × durata × n. persone. Incontri in remoto inclusi.
A6: Giornate back office | C6: =WBS!U14 | D6: gg-uomo | E6: STIME Impresoft: il contratto non quantifica il back office.
A7: Giornate di viaggio | C7: =WBS!V14 | D7: gg-uomo | E7: Solo fasi in presenza. Incluse nel monte ore.
A8: TOTALE giornate-uomo di progetto | C8: =WBS!X14 | D8: gg-uomo
A9: TOTALE ore di progetto | C9: =WBS!Y14 | D9: h | E9: Totale giornate × ore per giornata (Parametri!$C$6).
A11: › COSTO DELLE GIORNATE
A12: Costo ore front office | C12: =WBS!T14*Parametri!$C$6*Parametri!$C$7 | D12: €
A13: Costo ore back office | C13: =WBS!U14*Parametri!$C$6*Parametri!$C$8 | D13: €
A14: Costo ore di viaggio | C14: =WBS!V14*Parametri!$C$6*Parametri!$C$9 | D14: €
A15: COSTO TOTALE DELLE GIORNATE | C15: =WBS!Z14 | D15: €
A16: Quadratura (deve coincidere con la riga sopra) | C16: =SUM(C12:C14) | D16: € | E16: Controllo interno: se differisce c'è un errore di formula.
A18: › COSTO DELLE TRASFERTE — già incluso nell'investimento (Offerta § 10.1)
A19: Sessioni in presenza | C19: =SUMPRODUCT((WBS!$E$3:$E$13="In presenza")*WBS!$Q$3:$Q$13) | D19: n. | E19: Dalla WBS. L'Offerta § 10.1 include le trasferte per 6 incontri in presenza.
A20: Persone-sessione in trasferta | C20: =SUMPRODUCT((WBS!$E$3:$E$13="In presenza")*WBS!$Q$3:$Q$13*WBS!$S$3:$S$13) | D20: n. | E20: Somma delle presenze fisiche: determina il vitto.
A21: Viaggi in auto | C21: =IF(Parametri!$C$22=0,0,ROUNDUP(C20/Parametri!$C$22,0)) | D21: n. | E21: Persone-sessione ÷ persone per auto. Determina km e pedaggi.
A22: Ammortamento ACI | C22: =C21*Parametri!$C$18*Parametri!$C$19 | D22: € | E22: Viaggi × km a/r (Parametri!$C$18) × tariffa €/km (Parametri!$C$19).
A23: Pedaggi — casello | C23: =C21*Parametri!$C$20 | D23: €
A24: Vitto | C24: =C20*Parametri!$C$21 | D24: € | E24: Persone-sessione × costo per persona.
A25: TOTALE COSTO TRASFERTE | C25: =SUM(C22:C24) | D25: €
A27: › COSTO PIENO E MARGINE
A28: Costo delle giornate | C28: =C15 | D28: €
A29: Costo delle trasferte | C29: =C25 | D29: €
A30: COSTO PIENO DI PROGETTO | C30: =C28+C29 | D30: € | E30: Giornate + trasferte. È il costo da confrontare con l'investimento.
A31: Investimento contrattuale (una tantum) | C31: =Parametri!$C$14 | D31: € | E31: Offerta § 10. Le trasferte dei 6 incontri in presenza sono già dentro questa cifra.
A32: MARGINE DI PROGETTO | C32: =C31-C30 | D32: €
A33: Margine percentuale | C33: =IF(C31=0,"",C32/C31) | D33: % | E33: Se negativo la cella si inverte in nero.
A34: Tariffa media implicita sulle ore erogate | C34: =IF(C9=0,"",C31/C9) | D34: €/h | E34: Investimento ÷ totale ore. Da confrontare con le tre tariffe orarie impostate nei Parametri.
A36: › RIPARTIZIONE PER TIPO DI FASE
A37: Giornate — fasi con il cliente | C37: =SUMIF(WBS!$D$3:$D$13,"Cliente",WBS!$X$3:$X$13) | D37: gg-uomo
A38: Giornate — fasi interne | C38: =SUMIF(WBS!$D$3:$D$13,"Interna",WBS!$X$3:$X$13) | D38: gg-uomo
A39: Costo — fasi con il cliente | C39: =SUMIF(WBS!$D$3:$D$13,"Cliente",WBS!$Z$3:$Z$13) | D39: €
A40: Costo — fasi interne | C40: =SUMIF(WBS!$D$3:$D$13,"Interna",WBS!$Z$3:$Z$13) | D40: €
A41: Fasi con il cliente / fasi interne | C41: =COUNTIF(WBS!$D$3:$D$13,"Cliente")&" / "&COUNTIF(WBS!$D$3:$D$13,"Interna")
A43: › LEAD TIME
A44: Somma delle durate delle fasi, se svolte in sequenza | C44: =SUM(WBS!H3:H13) | D44: settimane
A45: Lead time di calendario effettivo | C45: =MAX(WBS!I3:I13)-MIN(WBS!G3:G13)+1 | D45: settimane | E45: Prima settimana di inizio → ultima settimana di fine, fasi sovrapposte incluse.
A46: Settimane recuperate dalla parallelizzazione | C46: =C44-C45 | D46: settimane
...

Sheet Sheet

Sheet Parametri
A1: › PARAMETRI DI CALCOLO
A2: Le celle con riquadro nero, sotto l'intestazione gialla, sono da compilare. Tutto il file si ricalcola da qui: giornate front office e viaggio, ore, costi e costo delle trasferte.
A4: Parametro | C4: Valore | D4: Unità | E4: Note
A5: › IMPEGNO E TARIFFE
A6: Ore per giornata | C6: 8 | D6: h | E6: Base di conversione giornate → ore.
A7: Tariffa oraria — Front office | C7: 95 | D7: €/h | E7: Ore erogate al cliente, incontri in remoto inclusi.
A8: Tariffa oraria — Back office | C8: 85 | D8: €/h | E8: Lavoro interno: analisi, delivery, reportistica.
A9: Tariffa oraria — Viaggio | C9: 75 | D9: €/h | E9: Tempo di trasferimento. Incluso nel monte ore di progetto.
A10: Ore di viaggio per trasferta (a/r, per persona) | C10: 1.5 | D10: h | E10: Vicenza ↔ Barbarano Mossano, ~25 km per tratta.
A12: › PROGETTO
A13: Lead time target di progetto | C13: 10 | D13: settimane | E13: Offerta § 8. Il § 6 dichiara invece 8-10 settimane: incoerenza interna al contratto.
A14: Investimento contrattuale (una tantum) | C14: 27000 | D14: € | E14: Offerta § 10. Comprende già i costi di trasferta dei 6 incontri in presenza (§ 10.1).
A15: Anno di riferimento | C15: 2026 | D15: anno | E15: Serve al foglio Timeline per ricavare i mesi dalla settimana ISO di partenza.
A17: › COSTO DELLE TRASFERTE (già incluso nell'investimento)
A18: Km andata e ritorno per trasferta | C18: 50 | D18: km | E18: STIMA sulle sedi indicate al § 10.1 (Barbarano Mossano ↔ Vicenza).
A19: Ammortamento ACI | C19: 0.65 | D19: €/km | E19: Tariffa indicata al § 10.1 dell'Offerta per le trasferte fuori perimetro.
A20: Pedaggi — casello | C20: 6 | D20: €/auto/trasferta
A21: Vitto | C21: 20 | D21: €/persona/trasferta
A22: Persone per auto | C22: 3 | D22: n. | E22: Quante persone viaggiano insieme: determina il numero di viaggi auto.

Sheet Ruoli
A1: › TEAM DI PROGETTO — RUOLI E NOMI
A2: Ruolo | B2: Nome | C2: Seniority | D2: Presidio | E2: Note
A3: Commerciale | B3: Carlo Alberto Campione | C3: Senior | D3: Fase 1 — convocazione del kick-off | E3: Nell'Offerta è il Sales Manager, responsabile dell'Offerta.
A4: Project Manager | C4: Senior | D4: Fasi 1 → 11 — presidio di progetto | E4: Referente unico verso il Cliente (Offerta § 7). Owner del piano di lavoro.
A5: RevOps Consultant Senior | B5: Alessandro Bruti | C5: Senior | D5: Tutte le sessioni con il cliente | E5: Conduce i workshop. È il RevOps Consultant senior dell'Offerta.
A6: RevOps Consultant junior 1 | C6: Junior | D6: Sessioni con il cliente + back office | E6: Nell'Offerta le figure specialistiche sono CX Strategist, Process Analyst e Integration Expert.
A7: RevOps Consultant junior 2 | C7: Junior | D7: Sessioni con il cliente + back office | E7: Conduce le 5 interviste one-to-one della fase 5.
A9: Lato Laica S.p.A. (Offerta § 6 e § 9)
A10: Riccardo Dolcetta — Managing Director · Nicolò Zanuso — CFO · più, a seconda della sessione: CMO / Marketing Manager, CSO, referente servizio clienti, referenti IT e gestione dati, key user operativi.
